Workbook

Sheet ⚙️ Settings
B1: ⚙️ DZ Infotech — Settings & Configuration · SAMPLE (dummy training data)
B3: A. Bucket Allocation Rules (% auto-calculated from targets — must total ₹7,00,000)
B4: Bucket | C4: Target (₹) | D4: % of ₹7L
B5: Employee | C5: 250000 | D5: =IF($C$10=0,0,C5/$C$10) -> 0.5
B6: Probation Reserve | C6: 50000 | D6: =IF($C$10=0,0,C6/$C$10) -> 0.1
B7: Contrack Expense | C7: 75000 | D7: =IF($C$10=0,0,C7/$C$10) -> 0.15
B8: Profit | C8: 100000 | D8: =IF($C$10=0,0,C8/$C$10) -> 0.2
B9: Company Expense | C9: 25000 | D9: =IF($C$10=0,0,C9/$C$10) -> 0.05
B10: TOTAL TARGET | C10: =SUM(C5:C9) -> 500000 | D10: =IF(C10=0,0,SUM(D5:D9)) -> 1
B12: B. Monthly Revenue Goal & Deadline
B13: Goal | C13: Value | D13: Note
B14: Monthly Revenue Target | C14: 500000 | D14: What we aim to collect this month
B15: Monthly Revenue Deadline | C15: 46234 | D15: Enter as date e.g. 30-Jun-2026
B17: C. Founder Names
B18: Founder 1 Name | C18: Rohan
B19: Founder 2 Name | C19: Karan
B21: D. Color Legend
B22: Blue text = Input cell — you type here
B23: Black text = Formula — do not edit
B24: Green text = Linked / auto-calculated

Sheet 🟡 Leads
A1: 🟡 Lead Pipeline — Prospects Not Yet Closed
A2: # | B2: Client / Company | C2: Contact Person | D2: Phone | E2: Service Interested | F2: Expected Revenue | G2: Lead Source | H2: Lead Status | I2: Last Follow-up | J2: Next Follow-up | K2: Follow-up Notes | L2: Convert →
A3: =1 -> 1 | B3: NovaMart | C3: Kiran Patel | E3: Website | F3: 35000 | G3: Walk-in | H3: Proposal Sent | J3: 46215 | K3: Wants product catalog site | L3: ✅ Done? Add to Projects sheet →
A4: =2 -> 2 | B4: FitZone Gym | C4: Amit Shah | E4: Custom Software | F4: 45000 | G4: Referral | H4: Negotiating | J4: 46213 | K4: Membership tracking app | L4: ✅ Done? Add to Projects sheet →
A5: =3 -> 3 | B5: Kalyan Jewels | C5: Meera Joshi | E5: Website | F5: 50000 | G5: Instagram | H5: Demo Scheduled | J5: 46214 | L5: ✅ Done? Add to Projects sheet →
A6: =4 -> 4 | B6: UrbanBrew | C6: Sameer Rao | E6: Web App | F6: 28000 | G6: Cold Call | H6: Contacted | J6: 46216 | L6: ✅ Done? Add to Projects sheet →
A7: =5 -> 5 | B7: PrimeCare Clinic | C7: Dr. Nair | E7: Custom Software | F7: 60000 | G7: PA Network | H7: New | J7: 46217 | L7: ✅ Done? Add to Projects sheet →
A8: =6 -> 6 | B8: StyleHub | C8: Neha Verma | E8: Website | F8: 32000 | G8: Walk-in | H8: New | L8: ✅ Done? Add to Projects sheet →
A9: =7 -> 7 | L9: ✅ Done? Add to Projects sheet →
A10: =8 -> 8 | L10: ✅ Done? Add to Projects sheet →
A11: =9 -> 9 | L11: ✅ Done? Add to Projects sheet →
A12: =10 -> 10 | L12: ✅ Done? Add to Projects sheet →
A13: =11 -> 11 | L13: ✅ Done? Add to Projects sheet →
A14: =12 -> 12 | L14: ✅ Done? Add to Projects sheet →
A15: =13 -> 13 | L15: ✅ Done? Add to Projects sheet →
A16: =14 -> 14 | L16: ✅ Done? Add to Projects sheet →
A17: =15 -> 15 | L17: ✅ Done? Add to Projects sheet →
A18: =16 -> 16 | L18: ✅ Done? Add to Projects sheet →
A19: =17 -> 17 | L19: ✅ Done? Add to Projects sheet →
A20: =18 -> 18 | L20: ✅ Done? Add to Projects sheet →
A21: =19 -> 19 | L21: ✅ Done? Add to Projects sheet →
A22: =20 -> 20 | L22: ✅ Done? Add to Projects sheet →
A23: =21 -> 21 | L23: ✅ Done? Add to Projects sheet →
A24: =22 -> 22 | L24: ✅ Done? Add to Projects sheet →
A25: =23 -> 23 | L25: ✅ Done? Add to Projects sheet →
A26: =24 -> 24 | L26: ✅ Done? Add to Projects sheet →
A27: =25 -> 25 | L27: ✅ Done? Add to Projects sheet →
A28: =26 -> 26 | L28: ✅ Done? Add to Projects sheet →
A29: =27 -> 27 | L29: ✅ Done? Add to Projects sheet →
A30: =28 -> 28 | L30: ✅ Done? Add to Projects sheet →
A31: =29 -> 29 | L31: ✅ Done? Add to Projects sheet →
A32: =30 -> 30 | L32: ✅ Done? Add to Projects sheet →
A33: =31 -> 31 | L33: ✅ Done? Add to Projects sheet →
A34: =32 -> 32 | L34: ✅ Done? Add to Projects sheet →
A35: =33 -> 33 | L35: ✅ Done? Add to Projects sheet →
A36: =34 -> 34 | L36: ✅ Done? Add to Projects sheet →
A37: =35 -> 35 | L37: ✅ Done? Add to Projects sheet →
A38: =36 -> 36 | L38: ✅ Done? Add to Projects sheet →
A39: =37 -> 37 | L39: ✅ Done? Add to Projects sheet →
A40: =38 -> 38 | L40: ✅ Done? Add to Projects sheet →
...

Sheet 📋 Projects
A1: 📋 DZ Infotech — Project Tracker · SAMPLE (dummy training data)
A2: # | B2: Client Name | C2: Project Name | D2: Service Type | E2: Total Amount | F2: Amount Received | G2: Pending | H2: Incentive | I2: Net Received | J2: Employee Alloc | K2: Probation Alloc | L2: Contrack Alloc | M2: Profit Alloc | N2: Company Alloc | O2: Date Received | P2: Follow-up Date | Q2: Expected Completion | R2: Status | S2: Notes
A3: =1 -> 1 | B3: Acme Traders | C3: Business Website | D3: Website | E3: 40000 | F3: 20000 | G3: =IF(E3="","",E3-F3) -> 20000 | I3: =IF(F3="","",F3-IF(H3="",0,H3)) -> 20000 | J3: =IF($I3="","",$I3*'⚙️ Settings'!$D$5) -> 10000 | K3: =IF($I3="","",$I3*'⚙️ Settings'!$D$6) -> 2000 | L3: =IF($I3="","",$I3*'⚙️ Settings'!$D$7) -> 3000 | M3: =IF($I3="","",$I3*'⚙️ Settings'!$D$8) -> 4000 | N3: =IF($I3="","",$I3*'⚙️ Settings'!$D$9) -> 1000 | O3: 46208 | Q3: 46223 | R3: In Progress
A4: =2 -> 2 | B4: Sunrise Foods | C4: Inventory App | D4: Custom Software | E4: 60000 | F4: 60000 | G4: =IF(E4="","",E4-F4) -> 0 | I4: =IF(F4="","",F4-IF(H4="",0,H4)) -> 60000 | J4: =IF($I4="","",$I4*'⚙️ Settings'!$D$5) -> 30000 | K4: =IF($I4="","",$I4*'⚙️ Settings'!$D$6) -> 6000 | L4: =IF($I4="","",$I4*'⚙️ Settings'!$D$7) -> 9000 | M4: =IF($I4="","",$I4*'⚙️ Settings'!$D$8) -> 12000 | N4: =IF($I4="","",$I4*'⚙️ Settings'!$D$9) -> 3000 | O4: 46205 | Q4: 46218 | R4: Completed & Paid
A5: =3 -> 3 | B5: Metro Interiors | C5: Portfolio Site | D5: Website | E5: 30000 | F5: 15000 | G5: =IF(E5="","",E5-F5) -> 15000 | I5: =IF(F5="","",F5-IF(H5="",0,H5)) -> 15000 | J5: =IF($I5="","",$I5*'⚙️ Settings'!$D$5) -> 7500 | K5: =IF($I5="","",$I5*'⚙️ Settings'!$D$6) -> 1500 | L5: =IF($I5="","",$I5*'⚙️ Settings'!$D$7) -> 2250 | M5: =IF($I5="","",$I5*'⚙️ Settings'!$D$8) -> 3000 | N5: =IF($I5="","",$I5*'⚙️ Settings'!$D$9) -> 750 | O5: 46209 | Q5: 46221 | R5: In Progress
A6: =4 -> 4 | B6: BlueWave Tech | C6: CRM Setup | D6: Custom Software | E6: 50000 | F6: 25000 | G6: =IF(E6="","",E6-F6) -> 25000 | I6: =IF(F6="","",F6-IF(H6="",0,H6)) -> 25000 | J6: =IF($I6="","",$I6*'⚙️ Settings'!$D$5) -> 12500 | K6: =IF($I6="","",$I6*'⚙️ Settings'!$D$6) -> 2500 | L6: =IF($I6="","",$I6*'⚙️ Settings'!$D$7) -> 3750 | M6: =IF($I6="","",$I6*'⚙️ Settings'!$D$8) -> 5000 | N6: =IF($I6="","",$I6*'⚙️ Settings'!$D$9) -> 1250 | O6: 46207 | Q6: 46225 | R6: In Progress
A7: =5 -> 5 | B7: GreenLeaf Cafe | C7: Ordering Site | D7: Web App | E7: 25000 | F7: 0 | G7: =IF(E7="","",E7-F7) -> 25000 | I7: =IF(F7="","",F7-IF(H7="",0,H7)) -> 0 | J7: =IF($I7="","",$I7*'⚙️ Settings'!$D$5) -> 0 | K7: =IF($I7="","",$I7*'⚙️ Settings'!$D$6) -> 0 | L7: =IF($I7="","",$I7*'⚙️ Settings'!$D$7) -> 0 | M7: =IF($I7="","",$I7*'⚙️ Settings'!$D$8) -> 0 | N7: =IF($I7="","",$I7*'⚙️ Settings'!$D$9) -> 0 | Q7: 46228 | R7: On Hold
A8: =6 -> 6 | B8: Sharma Textiles | C8: E-commerce Store | D8: Website | E8: 80000 | F8: 40000 | G8: =IF(E8="","",E8-F8) -> 40000 | I8: =IF(F8="","",F8-IF(H8="",0,H8)) -> 40000 | J8: =IF($I8="","",$I8*'⚙️ Settings'!$D$5) -> 20000 | K8: =IF($I8="","",$I8*'⚙️ Settings'!$D$6) -> 4000 | L8: =IF($I8="","",$I8*'⚙️ Settings'!$D$7) -> 6000 | M8: =IF($I8="","",$I8*'⚙️ Settings'!$D$8) -> 8000 | N8: =IF($I8="","",$I8*'⚙️ Settings'!$D$9) -> 2000 | O8: 46206 | Q8: 46231 | R8: In Progress
A9: =7 -> 7 | G9: =IF(E9="","",E9-F9) | I9: =IF(F9="","",F9-IF(H9="",0,H9)) | J9: =IF($I9="","",$I9*'⚙️ Settings'!$D$5) | K9: =IF($I9="","",$I9*'⚙️ Settings'!$D$6) | L9: =IF($I9="","",$I9*'⚙️ Settings'!$D$7) | M9: =IF($I9="","",$I9*'⚙️ Settings'!$D$8) | N9: =IF($I9="","",$I9*'⚙️ Settings'!$D$9)
A10: =8 -> 8 | G10: =IF(E10="","",E10-F10) | I10: =IF(F10="","",F10-IF(H10="",0,H10)) | J10: =IF($I10="","",$I10*'⚙️ Settings'!$D$5) | K10: =IF($I10="","",$I10*'⚙️ Settings'!$D$6) | L10: =IF($I10="","",$I10*'⚙️ Settings'!$D$7) | M10: =IF($I10="","",$I10*'⚙️ Settings'!$D$8) | N10: =IF($I10="","",$I10*'⚙️ Settings'!$D$9)
A11: =9 -> 9 | G11: =IF(E11="","",E11-F11) | I11: =IF(F11="","",F11-IF(H11="",0,H11)) | J11: =IF($I11="","",$I11*'⚙️ Settings'!$D$5) | K11: =IF($I11="","",$I11*'⚙️ Settings'!$D$6) | L11: =IF($I11="","",$I11*'⚙️ Settings'!$D$7) | M11: =IF($I11="","",$I11*'⚙️ Settings'!$D$8) | N11: =IF($I11="","",$I11*'⚙️ Settings'!$D$9)
A12: =10 -> 10 | G12: =IF(E12="","",E12-F12) | I12: =IF(F12="","",F12-IF(H12="",0,H12)) | J12: =IF($I12="","",$I12*'⚙️ Settings'!$D$5) | K12: =IF($I12="","",$I12*'⚙️ Settings'!$D$6) | L12: =IF($I12="","",$I12*'⚙️ Settings'!$D$7) | M12: =IF($I12="","",$I12*'⚙️ Settings'!$D$8) | N12: =IF($I12="","",$I12*'⚙️ Settings'!$D$9)
A13: =11 -> 11 | G13: =IF(E13="","",E13-F13) | I13: =IF(F13="","",F13-IF(H13="",0,H13)) | J13: =IF($I13="","",$I13*'⚙️ Settings'!$D$5) | K13: =IF($I13="","",$I13*'⚙️ Settings'!$D$6) | L13: =IF($I13="","",$I13*'⚙️ Settings'!$D$7) | M13: =IF($I13="","",$I13*'⚙️ Settings'!$D$8) | N13: =IF($I13="","",$I13*'⚙️ Settings'!$D$9)
A14: =12 -> 12 | G14: =IF(E14="","",E14-F14) | I14: =IF(F14="","",F14-IF(H14="",0,H14)) | J14: =IF($I14="","",$I14*'⚙️ Settings'!$D$5) | K14: =IF($I14="","",$I14*'⚙️ Settings'!$D$6) | L14: =IF($I14="","",$I14*'⚙️ Settings'!$D$7) | M14: =IF($I14="","",$I14*'⚙️ Settings'!$D$8) | N14: =IF($I14="","",$I14*'⚙️ Settings'!$D$9)
A15: =13 -> 13 | G15: =IF(E15="","",E15-F15) | I15: =IF(F15="","",F15-IF(H15="",0,H15)) | J15: =IF($I15="","",$I15*'⚙️ Settings'!$D$5) | K15: =IF($I15="","",$I15*'⚙️ Settings'!$D$6) | L15: =IF($I15="","",$I15*'⚙️ Settings'!$D$7) | M15: =IF($I15="","",$I15*'⚙️ Settings'!$D$8) | N15: =IF($I15="","",$I15*'⚙️ Settings'!$D$9)
A16: =14 -> 14 | G16: =IF(E16="","",E16-F16) | I16: =IF(F16="","",F16-IF(H16="",0,H16)) | J16: =IF($I16="","",$I16*'⚙️ Settings'!$D$5) | K16: =IF($I16="","",$I16*'⚙️ Settings'!$D$6) | L16: =IF($I16="","",$I16*'⚙️ Settings'!$D$7) | M16: =IF($I16="","",$I16*'⚙️ Settings'!$D$8) | N16: =IF($I16="","",$I16*'⚙️ Settings'!$D$9)
A17: =15 -> 15 | G17: =IF(E17="","",E17-F17) | I17: =IF(F17="","",F17-IF(H17="",0,H17)) | J17: =IF($I17="","",$I17*'⚙️ Settings'!$D$5) | K17: =IF($I17="","",$I17*'⚙️ Settings'!$D$6) | L17: =IF($I17="","",$I17*'⚙️ Settings'!$D$7) | M17: =IF($I17="","",$I17*'⚙️ Settings'!$D$8) | N17: =IF($I17="","",$I17*'⚙️ Settings'!$D$9)
A18: =16 -> 16 | G18: =IF(E18="","",E18-F18) | I18: =IF(F18="","",F18-IF(H18="",0,H18)) | J18: =IF($I18="","",$I18*'⚙️ Settings'!$D$5) | K18: =IF($I18="","",$I18*'⚙️ Settings'!$D$6) | L18: =IF($I18="","",$I18*'⚙️ Settings'!$D$7) | M18: =IF($I18="","",$I18*'⚙️ Settings'!$D$8) | N18: =IF($I18="","",$I18*'⚙️ Settings'!$D$9)
A19: =17 -> 17 | G19: =IF(E19="","",E19-F19) | I19: =IF(F19="","",F19-IF(H19="",0,H19)) | J19: =IF($I19="","",$I19*'⚙️ Settings'!$D$5) | K19: =IF($I19="","",$I19*'⚙️ Settings'!$D$6) | L19: =IF($I19="","",$I19*'⚙️ Settings'!$D$7) | M19: =IF($I19="","",$I19*'⚙️ Settings'!$D$8) | N19: =IF($I19="","",$I19*'⚙️ Settings'!$D$9)
A20: =18 -> 18 | G20: =IF(E20="","",E20-F20) | I20: =IF(F20="","",F20-IF(H20="",0,H20)) | J20: =IF($I20="","",$I20*'⚙️ Settings'!$D$5) | K20: =IF($I20="","",$I20*'⚙️ Settings'!$D$6) | L20: =IF($I20="","",$I20*'⚙️ Settings'!$D$7) | M20: =IF($I20="","",$I20*'⚙️ Settings'!$D$8) | N20: =IF($I20="","",$I20*'⚙️ Settings'!$D$9)
A21: =19 -> 19 | G21: =IF(E21="","",E21-F21) | I21: =IF(F21="","",F21-IF(H21="",0,H21)) | J21: =IF($I21="","",$I21*'⚙️ Settings'!$D$5) | K21: =IF($I21="","",$I21*'⚙️ Settings'!$D$6) | L21: =IF($I21="","",$I21*'⚙️ Settings'!$D$7) | M21: =IF($I21="","",$I21*'⚙️ Settings'!$D$8) | N21: =IF($I21="","",$I21*'⚙️ Settings'!$D$9)
A22: =20 -> 20 | G22: =IF(E22="","",E22-F22) | I22: =IF(F22="","",F22-IF(H22="",0,H22)) | J22: =IF($I22="","",$I22*'⚙️ Settings'!$D$5) | K22: =IF($I22="","",$I22*'⚙️ Settings'!$D$6) | L22: =IF($I22="","",$I22*'⚙️ Settings'!$D$7) | M22: =IF($I22="","",$I22*'⚙️ Settings'!$D$8) | N22: =IF($I22="","",$I22*'⚙️ Settings'!$D$9)
A23: =21 -> 21 | G23: =IF(E23="","",E23-F23) | I23: =IF(F23="","",F23-IF(H23="",0,H23)) | J23: =IF($I23="","",$I23*'⚙️ Settings'!$D$5) | K23: =IF($I23="","",$I23*'⚙️ Settings'!$D$6) | L23: =IF($I23="","",$I23*'⚙️ Settings'!$D$7) | M23: =IF($I23="","",$I23*'⚙️ Settings'!$D$8) | N23: =IF($I23="","",$I23*'⚙️ Settings'!$D$9)
A24: =22 -> 22 | G24: =IF(E24="","",E24-F24) | I24: =IF(F24="","",F24-IF(H24="",0,H24)) | J24: =IF($I24="","",$I24*'⚙️ Settings'!$D$5) | K24: =IF($I24="","",$I24*'⚙️ Settings'!$D$6) | L24: =IF($I24="","",$I24*'⚙️ Settings'!$D$7) | M24: =IF($I24="","",$I24*'⚙️ Settings'!$D$8) | N24: =IF($I24="","",$I24*'⚙️ Settings'!$D$9)
A25: =23 -> 23 | G25: =IF(E25="","",E25-F25) | I25: =IF(F25="","",F25-IF(H25="",0,H25)) | J25: =IF($I25="","",$I25*'⚙️ Settings'!$D$5) | K25: =IF($I25="","",$I25*'⚙️ Settings'!$D$6) | L25: =IF($I25="","",$I25*'⚙️ Settings'!$D$7) | M25: =IF($I25="","",$I25*'⚙️ Settings'!$D$8) | N25: =IF($I25="","",$I25*'⚙️ Settings'!$D$9)
A26: =24 -> 24 | G26: =IF(E26="","",E26-F26) | I26: =IF(F26="","",F26-IF(H26="",0,H26)) | J26: =IF($I26="","",$I26*'⚙️ Settings'!$D$5) | K26: =IF($I26="","",$I26*'⚙️ Settings'!$D$6) | L26: =IF($I26="","",$I26*'⚙️ Settings'!$D$7) | M26: =IF($I26="","",$I26*'⚙️ Settings'!$D$8) | N26: =IF($I26="","",$I26*'⚙️ Settings'!$D$9)
A27: =25 -> 25 | G27: =IF(E27="","",E27-F27) | I27: =IF(F27="","",F27-IF(H27="",0,H27)) | J27: =IF($I27="","",$I27*'⚙️ Settings'!$D$5) | K27: =IF($I27="","",$I27*'⚙️ Settings'!$D$6) | L27: =IF($I27="","",$I27*'⚙️ Settings'!$D$7) | M27: =IF($I27="","",$I27*'⚙️ Settings'!$D$8) | N27: =IF($I27="","",$I27*'⚙️ Settings'!$D$9)
A28: =26 -> 26 | G28: =IF(E28="","",E28-F28) | I28: =IF(F28="","",F28-IF(H28="",0,H28)) | J28: =IF($I28="","",$I28*'⚙️ Settings'!$D$5) | K28: =IF($I28="","",$I28*'⚙️ Settings'!$D$6) | L28: =IF($I28="","",$I28*'⚙️ Settings'!$D$7) | M28: =IF($I28="","",$I28*'⚙️ Settings'!$D$8) | N28: =IF($I28="","",$I28*'⚙️ Settings'!$D$9)
A29: =27 -> 27 | G29: =IF(E29="","",E29-F29) | I29: =IF(F29="","",F29-IF(H29="",0,H29)) | J29: =IF($I29="","",$I29*'⚙️ Settings'!$D$5) | K29: =IF($I29="","",$I29*'⚙️ Settings'!$D$6) | L29: =IF($I29="","",$I29*'⚙️ Settings'!$D$7) | M29: =IF($I29="","",$I29*'⚙️ Settings'!$D$8) | N29: =IF($I29="","",$I29*'⚙️ Settings'!$D$9)
A30: =28 -> 28 | G30: =IF(E30="","",E30-F30) | I30: =IF(F30="","",F30-IF(H30="",0,H30)) | J30: =IF($I30="","",$I30*'⚙️ Settings'!$D$5) | K30: =IF($I30="","",$I30*'⚙️ Settings'!$D$6) | L30: =IF($I30="","",$I30*'⚙️ Settings'!$D$7) | M30: =IF($I30="","",$I30*'⚙️ Settings'!$D$8) | N30: =IF($I30="","",$I30*'⚙️ Settings'!$D$9)
A31: =29 -> 29 | G31: =IF(E31="","",E31-F31) | I31: =IF(F31="","",F31-IF(H31="",0,H31)) | J31: =IF($I31="","",$I31*'⚙️ Settings'!$D$5) | K31: =IF($I31="","",$I31*'⚙️ Settings'!$D$6) | L31: =IF($I31="","",$I31*'⚙️ Settings'!$D$7) | M31: =IF($I31="","",$I31*'⚙️ Settings'!$D$8) | N31: =IF($I31="","",$I31*'⚙️ Settings'!$D$9)
A32: =30 -> 30 | G32: =IF(E32="","",E32-F32) | I32: =IF(F32="","",F32-IF(H32="",0,H32)) | J32: =IF($I32="","",$I32*'⚙️ Settings'!$D$5) | K32: =IF($I32="","",$I32*'⚙️ Settings'!$D$6) | L32: =IF($I32="","",$I32*'⚙️ Settings'!$D$7) | M32: =IF($I32="","",$I32*'⚙️ Settings'!$D$8) | N32: =IF($I32="","",$I32*'⚙️ Settings'!$D$9)
A33: =31 -> 31 | G33: =IF(E33="","",E33-F33) | I33: =IF(F33="","",F33-IF(H33="",0,H33)) | J33: =IF($I33="","",$I33*'⚙️ Settings'!$D$5) | K33: =IF($I33="","",$I33*'⚙️ Settings'!$D$6) | L33: =IF($I33="","",$I33*'⚙️ Settings'!$D$7) | M33: =IF($I33="","",$I33*'⚙️ Settings'!$D$8) | N33: =IF($I33="","",$I33*'⚙️ Settings'!$D$9)
A34: =32 -> 32 | G34: =IF(E34="","",E34-F34) | I34: =IF(F34="","",F34-IF(H34="",0,H34)) | J34: =IF($I34="","",$I34*'⚙️ Settings'!$D$5) | K34: =IF($I34="","",$I34*'⚙️ Settings'!$D$6) | L34: =IF($I34="","",$I34*'⚙️ Settings'!$D$7) | M34: =IF($I34="","",$I34*'⚙️ Settings'!$D$8) | N34: =IF($I34="","",$I34*'⚙️ Settings'!$D$9)
A35: =33 -> 33 | G35: =IF(E35="","",E35-F35) | I35: =IF(F35="","",F35-IF(H35="",0,H35)) | J35: =IF($I35="","",$I35*'⚙️ Settings'!$D$5) | K35: =IF($I35="","",$I35*'⚙️ Settings'!$D$6) | L35: =IF($I35="","",$I35*'⚙️ Settings'!$D$7) | M35: =IF($I35="","",$I35*'⚙️ Settings'!$D$8) | N35: =IF($I35="","",$I35*'⚙️ Settings'!$D$9)
A36: =34 -> 34 | G36: =IF(E36="","",E36-F36) | I36: =IF(F36="","",F36-IF(H36="",0,H36)) | J36: =IF($I36="","",$I36*'⚙️ Settings'!$D$5) | K36: =IF($I36="","",$I36*'⚙️ Settings'!$D$6) | L36: =IF($I36="","",$I36*'⚙️ Settings'!$D$7) | M36: =IF($I36="","",$I36*'⚙️ Settings'!$D$8) | N36: =IF($I36="","",$I36*'⚙️ Settings'!$D$9)
A37: =35 -> 35 | G37: =IF(E37="","",E37-F37) | I37: =IF(F37="","",F37-IF(H37="",0,H37)) | J37: =IF($I37="","",$I37*'⚙️ Settings'!$D$5) | K37: =IF($I37="","",$I37*'⚙️ Settings'!$D$6) | L37: =IF($I37="","",$I37*'⚙️ Settings'!$D$7) | M37: =IF($I37="","",$I37*'⚙️ Settings'!$D$8) | N37: =IF($I37="","",$I37*'⚙️ Settings'!$D$9)
A38: =36 -> 36 | G38: =IF(E38="","",E38-F38) | I38: =IF(F38="","",F38-IF(H38="",0,H38)) | J38: =IF($I38="","",$I38*'⚙️ Settings'!$D$5) | K38: =IF($I38="","",$I38*'⚙️ Settings'!$D$6) | L38: =IF($I38="","",$I38*'⚙️ Settings'!$D$7) | M38: =IF($I38="","",$I38*'⚙️ Settings'!$D$8) | N38: =IF($I38="","",$I38*'⚙️ Settings'!$D$9)
A39: =37 -> 37 | G39: =IF(E39="","",E39-F39) | I39: =IF(F39="","",F39-IF(H39="",0,H39)) | J39: =IF($I39="","",$I39*'⚙️ Settings'!$D$5) | K39: =IF($I39="","",$I39*'⚙️ Settings'!$D$6) | L39: =IF($I39="","",$I39*'⚙️ Settings'!$D$7) | M39: =IF($I39="","",$I39*'⚙️ Settings'!$D$8) | N39: =IF($I39="","",$I39*'⚙️ Settings'!$D$9)
A40: =38 -> 38 | G40: =IF(E40="","",E40-F40) | I40: =IF(F40="","",F40-IF(H40="",0,H40)) | J40: =IF($I40="","",$I40*'⚙️ Settings'!$D$5) | K40: =IF($I40="","",$I40*'⚙️ Settings'!$D$6) | L40: =IF($I40="","",$I40*'⚙️ Settings'!$D$7) | M40: =IF($I40="","",$I40*'⚙️ Settings'!$D$8) | N40: =IF($I40="","",$I40*'⚙️ Settings'!$D$9)
...

Sheet 💰 Money Buckets
B1: 💰 Money Buckets — Cumulative Progress
B2: Bucket | C2: Target | D2: Current Balance | E2: Remaining | F2: Progress %
B3: Employee | C3: ='⚙️ Settings'!C5 -> 250000 | D3: =F11 -> 55000 | E3: =IF(C3=0,0,C3-D3) -> 195000 | F3: =IF(C3=0,"-",TEXT(MIN(D3/C3,1),"0.0%")) -> 22.0%
B4: Probation Reserve | C4: ='⚙️ Settings'!C6 -> 50000 | D4: =F12 -> 21000 | E4: =IF(C4=0,0,C4-D4) -> 29000 | F4: =IF(C4=0,"-",TEXT(MIN(D4/C4,1),"0.0%")) -> 42.0%
B5: Contrack Expense | C5: ='⚙️ Settings'!C7 -> 75000 | D5: =F13 -> 32000 | E5: =IF(C5=0,0,C5-D5) -> 43000 | F5: =IF(C5=0,"-",TEXT(MIN(D5/C5,1),"0.0%")) -> 42.7%
B6: Profit | C6: ='⚙️ Settings'!C8 -> 100000 | D6: =F14 -> 30000 | E6: =IF(C6=0,0,C6-D6) -> 70000 | F6: =IF(C6=0,"-",TEXT(MIN(D6/C6,1),"0.0%")) -> 30.0%
B7: Company Expense | C7: ='⚙️ Settings'!C9 -> 25000 | D7: =F15 -> 15000 | E7: =IF(C7=0,0,C7-D7) -> 10000 | F7: =IF(C7=0,"-",TEXT(MIN(D7/C7,1),"0.0%")) -> 60.0%
B9: 🔄 Bucket Movement Detail (Current = Opening + money in − money out) | H9: Setup snapshot — do not edit
B10: Bucket | C10: Opening Balance | D10: In (Projects) | E10: Out (Expenses) | F10: Current Balance | H10: Alloc base | I10: Spent base
B11: Employee | C11: 20000 | D11: =SUMIF('📋 Projects'!$B$3:$B$52,"?*",'📋 Projects'!J3:J52)-H11 -> 80000 | E11: =SUMIF('💸 Expense Log'!$C$3:$C$102,B11,'💸 Expense Log'!$E$3:$E$102)-I11 -> 45000 | F11: =C11+D11-E11 -> 55000 | H11: 0 | I11: 0
B12: Probation Reserve | C12: 5000 | D12: =SUMIF('📋 Projects'!$B$3:$B$52,"?*",'📋 Projects'!K3:K52)-H12 -> 16000 | E12: =SUMIF('💸 Expense Log'!$C$3:$C$102,B12,'💸 Expense Log'!$E$3:$E$102)-I12 -> 0 | F12: =C12+D12-E12 -> 21000 | H12: 0 | I12: 0
B13: Contrack Expense | C13: 10000 | D13: =SUMIF('📋 Projects'!$B$3:$B$52,"?*",'📋 Projects'!L3:L52)-H13 -> 24000 | E13: =SUMIF('💸 Expense Log'!$C$3:$C$102,B13,'💸 Expense Log'!$E$3:$E$102)-I13 -> 2000 | F13: =C13+D13-E13 -> 32000 | H13: 0 | I13: 0
B14: Profit | C14: 8000 | D14: =SUMIF('📋 Projects'!$B$3:$B$52,"?*",'📋 Projects'!M3:M52)-H14 -> 32000 | E14: =SUMIF('💸 Expense Log'!$C$3:$C$102,B14,'💸 Expense Log'!$E$3:$E$102)-I14 -> 10000 | F14: =C14+D14-E14 -> 30000 | H14: 0 | I14: 0
B15: Company Expense | C15: 12000 | D15: =SUMIF('📋 Projects'!$B$3:$B$52,"?*",'📋 Projects'!N3:N52)-H15 -> 8000 | E15: =SUMIF('💸 Expense Log'!$C$3:$C$102,B15,'💸 Expense Log'!$E$3:$E$102)-I15 -> 5000 | F15: =C15+D15-E15 -> 15000 | H15: 0 | I15: 0
B17: 📅 Monthly Revenue Goal
B18: Goal | C18: Target | D18: Collected This Month | E18: Remaining | F18: Days Left
B19: Monthly Revenue | C19: ='⚙️ Settings'!C14 -> 500000 | D19: =SUMPRODUCT(('📋 Projects'!F3:F52)*(ISNUMBER('📋 Projects'!O3:O52))*(MONTH('📋 Projects'!O3:O52)=MONTH(TODAY()))*(YEAR('📋 Projects'!O3:O52)=YEAR(TODAY()))) -> 160000 | E19: =IF(C19=0,0,C19-D19) -> 340000 | F19: =IF('⚙️ Settings'!C15="","-",MAX(0,'⚙️ Settings'!C15-TODAY())) -> 23
B21: ℹ️ Opening balances are your real bucket amounts at setup. Every project payment auto-splits across buckets by % (Settings). Expenses subtract from the matching bucket. All buckets also reflect in 🏦 Bank Balance.

Sheet 🔴 Pending Dues
A1: 🔴 Pending Dues Tracker — People We Owe
A2: # | B2: Person / Vendor | C2: Role / Work Done | D2: Total Owed | E2: Paid So Far | F2: Balance Remaining | G2: Status | H2: Last Payment Date | I2: Notes
A3: =1 -> 1 | B3: Rahul Sharma | C3: Freelance design | D3: 8000 | F3: =IF(D3="","",D3-IF(E3="",0,E3)) -> 8000 | G3: =IF(D3="","",IF(E3=D3,"Cleared",IF(E3>0,"Partially Paid","Pending"))) -> Pending
A4: =2 -> 2 | B4: Priya Designs | C4: Logo work | D4: 3000 | F4: =IF(D4="","",D4-IF(E4="",0,E4)) -> 3000 | G4: =IF(D4="","",IF(E4=D4,"Cleared",IF(E4>0,"Partially Paid","Pending"))) -> Pending
A5: =3 -> 3 | B5: TechSupply Co | C5: Hardware purchase | D5: 12000 | F5: =IF(D5="","",D5-IF(E5="",0,E5)) -> 12000 | G5: =IF(D5="","",IF(E5=D5,"Cleared",IF(E5>0,"Partially Paid","Pending"))) -> Pending
A6: =4 -> 4 | F6: =IF(D6="","",D6-IF(E6="",0,E6)) | G6: =IF(D6="","",IF(E6=D6,"Cleared",IF(E6>0,"Partially Paid","Pending")))
A7: =5 -> 5 | F7: =IF(D7="","",D7-IF(E7="",0,E7)) | G7: =IF(D7="","",IF(E7=D7,"Cleared",IF(E7>0,"Partially Paid","Pending")))
A8: =6 -> 6 | F8: =IF(D8="","",D8-IF(E8="",0,E8)) | G8: =IF(D8="","",IF(E8=D8,"Cleared",IF(E8>0,"Partially Paid","Pending")))
A9: =7 -> 7 | F9: =IF(D9="","",D9-IF(E9="",0,E9)) | G9: =IF(D9="","",IF(E9=D9,"Cleared",IF(E9>0,"Partially Paid","Pending")))
A10: =8 -> 8 | F10: =IF(D10="","",D10-IF(E10="",0,E10)) | G10: =IF(D10="","",IF(E10=D10,"Cleared",IF(E10>0,"Partially Paid","Pending")))
A11: =9 -> 9 | F11: =IF(D11="","",D11-IF(E11="",0,E11)) | G11: =IF(D11="","",IF(E11=D11,"Cleared",IF(E11>0,"Partially Paid","Pending")))
A12: =10 -> 10 | F12: =IF(D12="","",D12-IF(E12="",0,E12)) | G12: =IF(D12="","",IF(E12=D12,"Cleared",IF(E12>0,"Partially Paid","Pending")))
A13: =11 -> 11 | F13: =IF(D13="","",D13-IF(E13="",0,E13)) | G13: =IF(D13="","",IF(E13=D13,"Cleared",IF(E13>0,"Partially Paid","Pending")))
A14: =12 -> 12 | F14: =IF(D14="","",D14-IF(E14="",0,E14)) | G14: =IF(D14="","",IF(E14=D14,"Cleared",IF(E14>0,"Partially Paid","Pending")))
A15: =13 -> 13 | F15: =IF(D15="","",D15-IF(E15="",0,E15)) | G15: =IF(D15="","",IF(E15=D15,"Cleared",IF(E15>0,"Partially Paid","Pending")))
A16: =14 -> 14 | F16: =IF(D16="","",D16-IF(E16="",0,E16)) | G16: =IF(D16="","",IF(E16=D16,"Cleared",IF(E16>0,"Partially Paid","Pending")))
A17: =15 -> 15 | F17: =IF(D17="","",D17-IF(E17="",0,E17)) | G17: =IF(D17="","",IF(E17=D17,"Cleared",IF(E17>0,"Partially Paid","Pending")))
A18: =16 -> 16 | F18: =IF(D18="","",D18-IF(E18="",0,E18)) | G18: =IF(D18="","",IF(E18=D18,"Cleared",IF(E18>0,"Partially Paid","Pending")))
A19: =17 -> 17 | F19: =IF(D19="","",D19-IF(E19="",0,E19)) | G19: =IF(D19="","",IF(E19=D19,"Cleared",IF(E19>0,"Partially Paid","Pending")))
A20: =18 -> 18 | F20: =IF(D20="","",D20-IF(E20="",0,E20)) | G20: =IF(D20="","",IF(E20=D20,"Cleared",IF(E20>0,"Partially Paid","Pending")))
A21: =19 -> 19 | F21: =IF(D21="","",D21-IF(E21="",0,E21)) | G21: =IF(D21="","",IF(E21=D21,"Cleared",IF(E21>0,"Partially Paid","Pending")))
A22: =20 -> 20 | F22: =IF(D22="","",D22-IF(E22="",0,E22)) | G22: =IF(D22="","",IF(E22=D22,"Cleared",IF(E22>0,"Partially Paid","Pending")))
A23: =21 -> 21 | F23: =IF(D23="","",D23-IF(E23="",0,E23)) | G23: =IF(D23="","",IF(E23=D23,"Cleared",IF(E23>0,"Partially Paid","Pending")))
A24: =22 -> 22 | F24: =IF(D24="","",D24-IF(E24="",0,E24)) | G24: =IF(D24="","",IF(E24=D24,"Cleared",IF(E24>0,"Partially Paid","Pending")))
A25: =23 -> 23 | F25: =IF(D25="","",D25-IF(E25="",0,E25)) | G25: =IF(D25="","",IF(E25=D25,"Cleared",IF(E25>0,"Partially Paid","Pending")))
A26: =24 -> 24 | F26: =IF(D26="","",D26-IF(E26="",0,E26)) | G26: =IF(D26="","",IF(E26=D26,"Cleared",IF(E26>0,"Partially Paid","Pending")))
A27: =25 -> 25 | F27: =IF(D27="","",D27-IF(E27="",0,E27)) | G27: =IF(D27="","",IF(E27=D27,"Cleared",IF(E27>0,"Partially Paid","Pending")))
A28: =26 -> 26 | F28: =IF(D28="","",D28-IF(E28="",0,E28)) | G28: =IF(D28="","",IF(E28=D28,"Cleared",IF(E28>0,"Partially Paid","Pending")))
A29: =27 -> 27 | F29: =IF(D29="","",D29-IF(E29="",0,E29)) | G29: =IF(D29="","",IF(E29=D29,"Cleared",IF(E29>0,"Partially Paid","Pending")))
A30: =28 -> 28 | F30: =IF(D30="","",D30-IF(E30="",0,E30)) | G30: =IF(D30="","",IF(E30=D30,"Cleared",IF(E30>0,"Partially Paid","Pending")))
A31: =29 -> 29 | F31: =IF(D31="","",D31-IF(E31="",0,E31)) | G31: =IF(D31="","",IF(E31=D31,"Cleared",IF(E31>0,"Partially Paid","Pending")))
A32: =30 -> 30 | F32: =IF(D32="","",D32-IF(E32="",0,E32)) | G32: =IF(D32="","",IF(E32=D32,"Cleared",IF(E32>0,"Partially Paid","Pending")))
A33: TOTALS | D33: =SUMIF(D3:D32,">0",D3:D32) -> 23000 | E33: =SUMIF(D3:D32,">0",E3:E32) -> 0 | F33: =SUMIF(D3:D32,">0",F3:F32) -> 23000

Sheet 🏦 Bank Balance
B1: 🏦 Bank Balance & Reserve Tracker
B3: Live Bank Position (auto-updates)
B4: Opening Bank Balance (setup) | C4: 55000 | D4: Your real bank balance at setup — adjust to re-baseline anytime | G4: Setup baseline ↓
B5: + Received since setup | C5: =SUMIF('📋 Projects'!$B$3:$B$52,"?*",'📋 Projects'!$I$3:$I$52)-G5 -> 160000 | D5: Auto: net project money in since setup | G5: 0
B6: − Spent since setup | C6: =SUM('💸 Expense Log'!$E$3:$E$102)-G6 -> 62000 | D6: Auto: expenses logged since setup | G6: 0
B7: Total Bank Balance | C7: =C4+C5-C6 -> 153000 | D7: Auto: opening + money in − money out
B9: Reserved in Buckets (from 💰 Money Buckets)
B10: Employee | C10: ='💰 Money Buckets'!F11 -> 55000
B11: Probation Reserve | C11: ='💰 Money Buckets'!F12 -> 21000
B12: Contrack Expense | C12: ='💰 Money Buckets'!F13 -> 32000
B13: Profit | C13: ='💰 Money Buckets'!F14 -> 30000
B14: Company Expense | C14: ='💰 Money Buckets'!F15 -> 15000
B15: Total in Buckets | C15: =SUM(C10:C14) -> 153000 | D15: Sum of all 5 buckets
B16: Unreserved (Bank − Buckets) | C16: =C7-C15 -> 0 | D16: Cash not yet earmarked to a bucket
B18: ℹ️ Total Bank Balance now updates automatically: project payments add in, expenses subtract out. Adjust 'Opening Bank Balance' only if your real bank differs (then update the setup baseline cell beside it).
B20: Monthly Snapshot — Manual Log
B21: Month | C21: Bank Balance | D21: Notes
B22: June 2026
B23: July 2026
B24: August 2026
B25: September 2026
B26: October 2026
B27: November 2026

Sheet 💸 Expense Log
A1: 💸 Expense Log — Every Outflow Recorded
A2: # | B2: Date | C2: Category | D2: Payee / Description | E2: Amount | F2: Notes
A3: =1 -> 1 | B3: 46206 | C3: Employee | D3: Salary - June batch | E3: 15000
A4: =2 -> 2 | B4: 46208 | C4: Company Expense | D4: Office rent | E4: 5000
A5: =3 -> 3 | B5: 46209 | C5: Contrack Expense | D5: Server hosting | E5: 2000
A6: =4 -> 4 | B6: 46210 | C6: Profit | D6: Founder withdrawal | E6: 10000
A7: =5 -> 5 | B7: 46241 | C7: Employee | D7: Salary - June batch | E7: 30000
A8: =6 -> 6
A9: =7 -> 7
A10: =8 -> 8
A11: =9 -> 9
A12: =10 -> 10
A13: =11 -> 11
A14: =12 -> 12
A15: =13 -> 13
A16: =14 -> 14
A17: =15 -> 15
A18: =16 -> 16
A19: =17 -> 17
A20: =18 -> 18
A21: =19 -> 19
A22: =20 -> 20
A23: =21 -> 21
A24: =22 -> 22
A25: =23 -> 23
A26: =24 -> 24
A27: =25 -> 25
A28: =26 -> 26
A29: =27 -> 27
A30: =28 -> 28
A31: =29 -> 29
A32: =30 -> 30
A33: =31 -> 31
A34: =32 -> 32
A35: =33 -> 33
A36: =34 -> 34
A37: =35 -> 35
A38: =36 -> 36
A39: =37 -> 37
A40: =38 -> 38
...
